2017-10-28 16:30:03,464 [INFO] kubeshell.main cli:14 - session start
2017-10-28 16:30:03,465 [INFO] kubeshell.kubeshell run_cli:142 - running kube-shell event loop
2017-10-28 17:00:35,206 [INFO] kubeshell.main cli:14 - session start
2017-10-28 17:00:35,206 [INFO] kubeshell.kubeshell run_cli:142 - running kube-shell event loop
2017-10-28 18:07:33,567 [INFO] kubeshell.main cli:14 - session start
2017-10-28 18:07:33,568 [INFO] kubeshell.kubeshell run_cli:142 - running kube-shell event loop
2017-10-29 14:38:21,381 [INFO] kubeshell.main cli:14 - session start
2017-10-29 14:38:21,382 [INFO] kubeshell.kubeshell run_cli:142 - running kube-shell event loop
2017-10-29 17:29:46,932 [INFO] kubeshell.main cli:14 - session start
2017-10-29 17:29:46,932 [INFO] kubeshell.kubeshell run_cli:142 - running kube-shell event loop
2017-11-05 12:51:46,795 [INFO] kubeshell.main cli:14 - session start
2017-11-05 12:51:46,813 [INFO] kubeshell.kubeshell run_cli:142 - running kube-shell event loop
2017-11-11 09:36:22,193 [INFO] kubeshell.main cli:14 - session start
2017-11-11 09:36:22,211 [INFO] kubeshell.kubeshell run_cli:142 - running kube-shell event loop
2017-11-11 10:14:26,974 [INFO] kubeshell.main cli:14 - session start
2017-11-11 10:14:26,974 [INFO] kubeshell.kubeshell run_cli:142 - running kube-shell event loop
2017-11-11 10:22:51,671 [INFO] kubeshell.main cli:14 - session start
2017-11-11 10:22:51,672 [INFO] kubeshell.kubeshell run_cli:142 - running kube-shell event loop
2017-11-11 13:01:17,818 [INFO] kubeshell.main cli:14 - session start
2017-11-11 13:01:17,828 [INFO] kubeshell.kubeshell run_cli:142 - running kube-shell event loop
2017-11-11 14:26:21,834 [WARNING] kubeshell.client __init__:21 - unable to load kube-config
2017-11-11 14:26:21,886 [WARNING] kubeshell.client __init__:21 - unable to load kube-config
2017-11-11 14:26:21,890 [INFO] kubeshell.main cli:14 - session start
2017-11-11 14:26:21,891 [INFO] kubeshell.kubeshell run_cli:142 - running kube-shell event loop
2017-11-11 14:26:41,102 [WARNING] kubeshell.client get_resource:40 - unable to connect to k8 cluster
Traceback (most recent call last):
  File "/home/linuxbrew/.linuxbrew/opt/python3/lib/python3.6/site-packages/urllib3/connection.py", line 141, in _new_conn
    (self.host, self.port), self.timeout, **extra_kw)
  File "/home/linuxbrew/.linuxbrew/opt/python3/lib/python3.6/site-packages/urllib3/util/connection.py", line 83, in create_connection
    raise err
  File "/home/linuxbrew/.linuxbrew/opt/python3/lib/python3.6/site-packages/urllib3/util/connection.py", line 73, in create_connection
    sock.connect(sa)
ConnectionRefusedError: [Errno 111] Connection refused

During handling of the above exception, another exception occurred:

Traceback (most recent call last):
  File "/home/linuxbrew/.linuxbrew/opt/python3/lib/python3.6/site-packages/urllib3/connectionpool.py", line 601, in urlopen
    chunked=chunked)
  File "/home/linuxbrew/.linuxbrew/opt/python3/lib/python3.6/site-packages/urllib3/connectionpool.py", line 346, in _make_request
    self._validate_conn(conn)
  File "/home/linuxbrew/.linuxbrew/opt/python3/lib/python3.6/site-packages/urllib3/connectionpool.py", line 850, in _validate_conn
    conn.connect()
  File "/home/linuxbrew/.linuxbrew/opt/python3/lib/python3.6/site-packages/urllib3/connection.py", line 284, in connect
    conn = self._new_conn()
  File "/home/linuxbrew/.linuxbrew/opt/python3/lib/python3.6/site-packages/urllib3/connection.py", line 150, in _new_conn
    self, "Failed to establish a new connection: %s" % e)
urllib3.exceptions.NewConnectionError: <urllib3.connection.VerifiedHTTPSConnection object at 0x7fc9a35ebf60>: Failed to establish a new connection: [Errno 111] Connection refused

During handling of the above exception, another exception occurred:

Traceback (most recent call last):
  File "/home/linuxbrew/.linuxbrew/opt/python3/lib/python3.6/site-packages/kubeshell/client.py", line 35, in get_resource
    ret, namespaced_resource = self._call_api_client(resource)
  File "/home/linuxbrew/.linuxbrew/opt/python3/lib/python3.6/site-packages/kubeshell/client.py", line 65, in _call_api_client
    ret = self.v1.list_namespace(watch=False)
  File "/home/linuxbrew/.linuxbrew/opt/python3/lib/python3.6/site-packages/kubernetes/client/apis/core_v1_api.py", line 11614, in list_namespace
    (data) = self.list_namespace_with_http_info(**kwargs)
  File "/home/linuxbrew/.linuxbrew/opt/python3/lib/python3.6/site-packages/kubernetes/client/apis/core_v1_api.py", line 11707, in list_namespace_with_http_info
    collection_formats=collection_formats)
  File "/home/linuxbrew/.linuxbrew/opt/python3/lib/python3.6/site-packages/kubernetes/client/api_client.py", line 329, in call_api
    _return_http_data_only, collection_formats, _preload_content, _request_timeout)
  File "/home/linuxbrew/.linuxbrew/opt/python3/lib/python3.6/site-packages/kubernetes/client/api_client.py", line 153, in __call_api
    _request_timeout=_request_timeout)
  File "/home/linuxbrew/.linuxbrew/opt/python3/lib/python3.6/site-packages/kubernetes/client/api_client.py", line 361, in request
    headers=headers)
  File "/home/linuxbrew/.linuxbrew/opt/python3/lib/python3.6/site-packages/kubernetes/client/rest.py", line 240, in GET
    query_params=query_params)
  File "/home/linuxbrew/.linuxbrew/opt/python3/lib/python3.6/site-packages/kubernetes/client/rest.py", line 214, in request
    headers=headers)
  File "/home/linuxbrew/.linuxbrew/opt/python3/lib/python3.6/site-packages/urllib3/request.py", line 66, in request
    **urlopen_kw)
  File "/home/linuxbrew/.linuxbrew/opt/python3/lib/python3.6/site-packages/urllib3/request.py", line 87, in request_encode_url
    return self.urlopen(method, url, **extra_kw)
  File "/home/linuxbrew/.linuxbrew/opt/python3/lib/python3.6/site-packages/urllib3/poolmanager.py", line 321, in urlopen
    response = conn.urlopen(method, u.request_uri, **kw)
  File "/home/linuxbrew/.linuxbrew/opt/python3/lib/python3.6/site-packages/urllib3/connectionpool.py", line 668, in urlopen
    **response_kw)
  File "/home/linuxbrew/.linuxbrew/opt/python3/lib/python3.6/site-packages/urllib3/connectionpool.py", line 668, in urlopen
    **response_kw)
  File "/home/linuxbrew/.linuxbrew/opt/python3/lib/python3.6/site-packages/urllib3/connectionpool.py", line 668, in urlopen
    **response_kw)
  File "/home/linuxbrew/.linuxbrew/opt/python3/lib/python3.6/site-packages/urllib3/connectionpool.py", line 639, in urlopen
    _stacktrace=sys.exc_info()[2])
  File "/home/linuxbrew/.linuxbrew/opt/python3/lib/python3.6/site-packages/urllib3/util/retry.py", line 388, in increment
    raise MaxRetryError(_pool, url, error or ResponseError(cause))
urllib3.exceptions.MaxRetryError: HTTPSConnectionPool(host='localhost', port=443): Max retries exceeded with url: /api/v1/namespaces?watch=False (Caused by NewConnectionError('<urllib3.connection.VerifiedHTTPSConnection object at 0x7fc9a35ebf60>: Failed to establish a new connection: [Errno 111] Connection refused',))
2017-11-11 14:26:45,147 [WARNING] kubeshell.client get_resource:40 - unable to connect to k8 cluster
Traceback (most recent call last):
  File "/home/linuxbrew/.linuxbrew/opt/python3/lib/python3.6/site-packages/urllib3/connection.py", line 141, in _new_conn
    (self.host, self.port), self.timeout, **extra_kw)
  File "/home/linuxbrew/.linuxbrew/opt/python3/lib/python3.6/site-packages/urllib3/util/connection.py", line 83, in create_connection
    raise err
  File "/home/linuxbrew/.linuxbrew/opt/python3/lib/python3.6/site-packages/urllib3/util/connection.py", line 73, in create_connection
    sock.connect(sa)
ConnectionRefusedError: [Errno 111] Connection refused

During handling of the above exception, another exception occurred:

Traceback (most recent call last):
  File "/home/linuxbrew/.linuxbrew/opt/python3/lib/python3.6/site-packages/urllib3/connectionpool.py", line 601, in urlopen
    chunked=chunked)
  File "/home/linuxbrew/.linuxbrew/opt/python3/lib/python3.6/site-packages/urllib3/connectionpool.py", line 346, in _make_request
    self._validate_conn(conn)
  File "/home/linuxbrew/.linuxbrew/opt/python3/lib/python3.6/site-packages/urllib3/connectionpool.py", line 850, in _validate_conn
    conn.connect()
  File "/home/linuxbrew/.linuxbrew/opt/python3/lib/python3.6/site-packages/urllib3/connection.py", line 284, in connect
    conn = self._new_conn()
  File "/home/linuxbrew/.linuxbrew/opt/python3/lib/python3.6/site-packages/urllib3/connection.py", line 150, in _new_conn
    self, "Failed to establish a new connection: %s" % e)
urllib3.exceptions.NewConnectionError: <urllib3.connection.VerifiedHTTPSConnection object at 0x7fc9a363de80>: Failed to establish a new connection: [Errno 111] Connection refused

During handling of the above exception, another exception occurred:

Traceback (most recent call last):
  File "/home/linuxbrew/.linuxbrew/opt/python3/lib/python3.6/site-packages/kubeshell/client.py", line 35, in get_resource
    ret, namespaced_resource = self._call_api_client(resource)
  File "/home/linuxbrew/.linuxbrew/opt/python3/lib/python3.6/site-packages/kubeshell/client.py", line 65, in _call_api_client
    ret = self.v1.list_namespace(watch=False)
  File "/home/linuxbrew/.linuxbrew/opt/python3/lib/python3.6/site-packages/kubernetes/client/apis/core_v1_api.py", line 11614, in list_namespace
    (data) = self.list_namespace_with_http_info(**kwargs)
  File "/home/linuxbrew/.linuxbrew/opt/python3/lib/python3.6/site-packages/kubernetes/client/apis/core_v1_api.py", line 11707, in list_namespace_with_http_info
    collection_formats=collection_formats)
  File "/home/linuxbrew/.linuxbrew/opt/python3/lib/python3.6/site-packages/kubernetes/client/api_client.py", line 329, in call_api
    _return_http_data_only, collection_formats, _preload_content, _request_timeout)
  File "/home/linuxbrew/.linuxbrew/opt/python3/lib/python3.6/site-packages/kubernetes/client/api_client.py", line 153, in __call_api
    _request_timeout=_request_timeout)
  File "/home/linuxbrew/.linuxbrew/opt/python3/lib/python3.6/site-packages/kubernetes/client/api_client.py", line 361, in request
    headers=headers)
  File "/home/linuxbrew/.linuxbrew/opt/python3/lib/python3.6/site-packages/kubernetes/client/rest.py", line 240, in GET
    query_params=query_params)
  File "/home/linuxbrew/.linuxbrew/opt/python3/lib/python3.6/site-packages/kubernetes/client/rest.py", line 214, in request
    headers=headers)
  File "/home/linuxbrew/.linuxbrew/opt/python3/lib/python3.6/site-packages/urllib3/request.py", line 66, in request
    **urlopen_kw)
  File "/home/linuxbrew/.linuxbrew/opt/python3/lib/python3.6/site-packages/urllib3/request.py", line 87, in request_encode_url
    return self.urlopen(method, url, **extra_kw)
  File "/home/linuxbrew/.linuxbrew/opt/python3/lib/python3.6/site-packages/urllib3/poolmanager.py", line 321, in urlopen
    response = conn.urlopen(method, u.request_uri, **kw)
  File "/home/linuxbrew/.linuxbrew/opt/python3/lib/python3.6/site-packages/urllib3/connectionpool.py", line 668, in urlopen
    **response_kw)
  File "/home/linuxbrew/.linuxbrew/opt/python3/lib/python3.6/site-packages/urllib3/connectionpool.py", line 668, in urlopen
    **response_kw)
  File "/home/linuxbrew/.linuxbrew/opt/python3/lib/python3.6/site-packages/urllib3/connectionpool.py", line 668, in urlopen
    **response_kw)
  File "/home/linuxbrew/.linuxbrew/opt/python3/lib/python3.6/site-packages/urllib3/connectionpool.py", line 639, in urlopen
    _stacktrace=sys.exc_info()[2])
  File "/home/linuxbrew/.linuxbrew/opt/python3/lib/python3.6/site-packages/urllib3/util/retry.py", line 388, in increment
    raise MaxRetryError(_pool, url, error or ResponseError(cause))
urllib3.exceptions.MaxRetryError: HTTPSConnectionPool(host='localhost', port=443): Max retries exceeded with url: /api/v1/namespaces?watch=False (Caused by NewConnectionError('<urllib3.connection.VerifiedHTTPSConnection object at 0x7fc9a363de80>: Failed to establish a new connection: [Errno 111] Connection refused',))
2017-11-11 14:26:49,162 [WARNING] kubeshell.client get_resource:40 - unable to connect to k8 cluster
Traceback (most recent call last):
  File "/home/linuxbrew/.linuxbrew/opt/python3/lib/python3.6/site-packages/urllib3/connection.py", line 141, in _new_conn
    (self.host, self.port), self.timeout, **extra_kw)
  File "/home/linuxbrew/.linuxbrew/opt/python3/lib/python3.6/site-packages/urllib3/util/connection.py", line 83, in create_connection
    raise err
  File "/home/linuxbrew/.linuxbrew/opt/python3/lib/python3.6/site-packages/urllib3/util/connection.py", line 73, in create_connection
    sock.connect(sa)
ConnectionRefusedError: [Errno 111] Connection refused

During handling of the above exception, another exception occurred:

Traceback (most recent call last):
  File "/home/linuxbrew/.linuxbrew/opt/python3/lib/python3.6/site-packages/urllib3/connectionpool.py", line 601, in urlopen
    chunked=chunked)
  File "/home/linuxbrew/.linuxbrew/opt/python3/lib/python3.6/site-packages/urllib3/connectionpool.py", line 346, in _make_request
    self._validate_conn(conn)
  File "/home/linuxbrew/.linuxbrew/opt/python3/lib/python3.6/site-packages/urllib3/connectionpool.py", line 850, in _validate_conn
    conn.connect()
  File "/home/linuxbrew/.linuxbrew/opt/python3/lib/python3.6/site-packages/urllib3/connection.py", line 284, in connect
    conn = self._new_conn()
  File "/home/linuxbrew/.linuxbrew/opt/python3/lib/python3.6/site-packages/urllib3/connection.py", line 150, in _new_conn
    self, "Failed to establish a new connection: %s" % e)
urllib3.exceptions.NewConnectionError: <urllib3.connection.VerifiedHTTPSConnection object at 0x7fc9a1cd19b0>: Failed to establish a new connection: [Errno 111] Connection refused

During handling of the above exception, another exception occurred:

Traceback (most recent call last):
  File "/home/linuxbrew/.linuxbrew/opt/python3/lib/python3.6/site-packages/kubeshell/client.py", line 35, in get_resource
    ret, namespaced_resource = self._call_api_client(resource)
  File "/home/linuxbrew/.linuxbrew/opt/python3/lib/python3.6/site-packages/kubeshell/client.py", line 65, in _call_api_client
    ret = self.v1.list_namespace(watch=False)
  File "/home/linuxbrew/.linuxbrew/opt/python3/lib/python3.6/site-packages/kubernetes/client/apis/core_v1_api.py", line 11614, in list_namespace
    (data) = self.list_namespace_with_http_info(**kwargs)
  File "/home/linuxbrew/.linuxbrew/opt/python3/lib/python3.6/site-packages/kubernetes/client/apis/core_v1_api.py", line 11707, in list_namespace_with_http_info
    collection_formats=collection_formats)
  File "/home/linuxbrew/.linuxbrew/opt/python3/lib/python3.6/site-packages/kubernetes/client/api_client.py", line 329, in call_api
    _return_http_data_only, collection_formats, _preload_content, _request_timeout)
  File "/home/linuxbrew/.linuxbrew/opt/python3/lib/python3.6/site-packages/kubernetes/client/api_client.py", line 153, in __call_api
    _request_timeout=_request_timeout)
  File "/home/linuxbrew/.linuxbrew/opt/python3/lib/python3.6/site-packages/kubernetes/client/api_client.py", line 361, in request
    headers=headers)
  File "/home/linuxbrew/.linuxbrew/opt/python3/lib/python3.6/site-packages/kubernetes/client/rest.py", line 240, in GET
    query_params=query_params)
  File "/home/linuxbrew/.linuxbrew/opt/python3/lib/python3.6/site-packages/kubernetes/client/rest.py", line 214, in request
    headers=headers)
  File "/home/linuxbrew/.linuxbrew/opt/python3/lib/python3.6/site-packages/urllib3/request.py", line 66, in request
    **urlopen_kw)
  File "/home/linuxbrew/.linuxbrew/opt/python3/lib/python3.6/site-packages/urllib3/request.py", line 87, in request_encode_url
    return self.urlopen(method, url, **extra_kw)
  File "/home/linuxbrew/.linuxbrew/opt/python3/lib/python3.6/site-packages/urllib3/poolmanager.py", line 321, in urlopen
    response = conn.urlopen(method, u.request_uri, **kw)
  File "/home/linuxbrew/.linuxbrew/opt/python3/lib/python3.6/site-packages/urllib3/connectionpool.py", line 668, in urlopen
    **response_kw)
  File "/home/linuxbrew/.linuxbrew/opt/python3/lib/python3.6/site-packages/urllib3/connectionpool.py", line 668, in urlopen
    **response_kw)
  File "/home/linuxbrew/.linuxbrew/opt/python3/lib/python3.6/site-packages/urllib3/connectionpool.py", line 668, in urlopen
    **response_kw)
  File "/home/linuxbrew/.linuxbrew/opt/python3/lib/python3.6/site-packages/urllib3/connectionpool.py", line 639, in urlopen
    _stacktrace=sys.exc_info()[2])
  File "/home/linuxbrew/.linuxbrew/opt/python3/lib/python3.6/site-packages/urllib3/util/retry.py", line 388, in increment
    raise MaxRetryError(_pool, url, error or ResponseError(cause))
urllib3.exceptions.MaxRetryError: HTTPSConnectionPool(host='localhost', port=443): Max retries exceeded with url: /api/v1/namespaces?watch=False (Caused by NewConnectionError('<urllib3.connection.VerifiedHTTPSConnection object at 0x7fc9a1cd19b0>: Failed to establish a new connection: [Errno 111] Connection refused',))
2017-11-11 14:27:00,778 [WARNING] kubeshell.client get_resource:40 - unable to connect to k8 cluster
Traceback (most recent call last):
  File "/home/linuxbrew/.linuxbrew/opt/python3/lib/python3.6/site-packages/urllib3/connection.py", line 141, in _new_conn
    (self.host, self.port), self.timeout, **extra_kw)
  File "/home/linuxbrew/.linuxbrew/opt/python3/lib/python3.6/site-packages/urllib3/util/connection.py", line 83, in create_connection
    raise err
  File "/home/linuxbrew/.linuxbrew/opt/python3/lib/python3.6/site-packages/urllib3/util/connection.py", line 73, in create_connection
    sock.connect(sa)
ConnectionRefusedError: [Errno 111] Connection refused

During handling of the above exception, another exception occurred:

Traceback (most recent call last):
  File "/home/linuxbrew/.linuxbrew/opt/python3/lib/python3.6/site-packages/urllib3/connectionpool.py", line 601, in urlopen
    chunked=chunked)
  File "/home/linuxbrew/.linuxbrew/opt/python3/lib/python3.6/site-packages/urllib3/connectionpool.py", line 346, in _make_request
    self._validate_conn(conn)
  File "/home/linuxbrew/.linuxbrew/opt/python3/lib/python3.6/site-packages/urllib3/connectionpool.py", line 850, in _validate_conn
    conn.connect()
  File "/home/linuxbrew/.linuxbrew/opt/python3/lib/python3.6/site-packages/urllib3/connection.py", line 284, in connect
    conn = self._new_conn()
  File "/home/linuxbrew/.linuxbrew/opt/python3/lib/python3.6/site-packages/urllib3/connection.py", line 150, in _new_conn
    self, "Failed to establish a new connection: %s" % e)
urllib3.exceptions.NewConnectionError: <urllib3.connection.VerifiedHTTPSConnection object at 0x7fc9a1c50630>: Failed to establish a new connection: [Errno 111] Connection refused

During handling of the above exception, another exception occurred:

Traceback (most recent call last):
  File "/home/linuxbrew/.linuxbrew/opt/python3/lib/python3.6/site-packages/kubeshell/client.py", line 35, in get_resource
    ret, namespaced_resource = self._call_api_client(resource)
  File "/home/linuxbrew/.linuxbrew/opt/python3/lib/python3.6/site-packages/kubeshell/client.py", line 65, in _call_api_client
    ret = self.v1.list_namespace(watch=False)
  File "/home/linuxbrew/.linuxbrew/opt/python3/lib/python3.6/site-packages/kubernetes/client/apis/core_v1_api.py", line 11614, in list_namespace
    (data) = self.list_namespace_with_http_info(**kwargs)
  File "/home/linuxbrew/.linuxbrew/opt/python3/lib/python3.6/site-packages/kubernetes/client/apis/core_v1_api.py", line 11707, in list_namespace_with_http_info
    collection_formats=collection_formats)
  File "/home/linuxbrew/.linuxbrew/opt/python3/lib/python3.6/site-packages/kubernetes/client/api_client.py", line 329, in call_api
    _return_http_data_only, collection_formats, _preload_content, _request_timeout)
  File "/home/linuxbrew/.linuxbrew/opt/python3/lib/python3.6/site-packages/kubernetes/client/api_client.py", line 153, in __call_api
    _request_timeout=_request_timeout)
  File "/home/linuxbrew/.linuxbrew/opt/python3/lib/python3.6/site-packages/kubernetes/client/api_client.py", line 361, in request
    headers=headers)
  File "/home/linuxbrew/.linuxbrew/opt/python3/lib/python3.6/site-packages/kubernetes/client/rest.py", line 240, in GET
    query_params=query_params)
  File "/home/linuxbrew/.linuxbrew/opt/python3/lib/python3.6/site-packages/kubernetes/client/rest.py", line 214, in request
    headers=headers)
  File "/home/linuxbrew/.linuxbrew/opt/python3/lib/python3.6/site-packages/urllib3/request.py", line 66, in request
    **urlopen_kw)
  File "/home/linuxbrew/.linuxbrew/opt/python3/lib/python3.6/site-packages/urllib3/request.py", line 87, in request_encode_url
    return self.urlopen(method, url, **extra_kw)
  File "/home/linuxbrew/.linuxbrew/opt/python3/lib/python3.6/site-packages/urllib3/poolmanager.py", line 321, in urlopen
    response = conn.urlopen(method, u.request_uri, **kw)
  File "/home/linuxbrew/.linuxbrew/opt/python3/lib/python3.6/site-packages/urllib3/connectionpool.py", line 668, in urlopen
    **response_kw)
  File "/home/linuxbrew/.linuxbrew/opt/python3/lib/python3.6/site-packages/urllib3/connectionpool.py", line 668, in urlopen
    **response_kw)
  File "/home/linuxbrew/.linuxbrew/opt/python3/lib/python3.6/site-packages/urllib3/connectionpool.py", line 668, in urlopen
    **response_kw)
  File "/home/linuxbrew/.linuxbrew/opt/python3/lib/python3.6/site-packages/urllib3/connectionpool.py", line 639, in urlopen
    _stacktrace=sys.exc_info()[2])
  File "/home/linuxbrew/.linuxbrew/opt/python3/lib/python3.6/site-packages/urllib3/util/retry.py", line 388, in increment
    raise MaxRetryError(_pool, url, error or ResponseError(cause))
urllib3.exceptions.MaxRetryError: HTTPSConnectionPool(host='localhost', port=443): Max retries exceeded with url: /api/v1/namespaces?watch=False (Caused by NewConnectionError('<urllib3.connection.VerifiedHTTPSConnection object at 0x7fc9a1c50630>: Failed to establish a new connection: [Errno 111] Connection refused',))
2017-11-11 14:27:04,793 [WARNING] kubeshell.client get_resource:40 - unable to connect to k8 cluster
Traceback (most recent call last):
  File "/home/linuxbrew/.linuxbrew/opt/python3/lib/python3.6/site-packages/urllib3/connection.py", line 141, in _new_conn
    (self.host, self.port), self.timeout, **extra_kw)
  File "/home/linuxbrew/.linuxbrew/opt/python3/lib/python3.6/site-packages/urllib3/util/connection.py", line 83, in create_connection
    raise err
  File "/home/linuxbrew/.linuxbrew/opt/python3/lib/python3.6/site-packages/urllib3/util/connection.py", line 73, in create_connection
    sock.connect(sa)
ConnectionRefusedError: [Errno 111] Connection refused

During handling of the above exception, another exception occurred:

Traceback (most recent call last):
  File "/home/linuxbrew/.linuxbrew/opt/python3/lib/python3.6/site-packages/urllib3/connectionpool.py", line 601, in urlopen
    chunked=chunked)
  File "/home/linuxbrew/.linuxbrew/opt/python3/lib/python3.6/site-packages/urllib3/connectionpool.py", line 346, in _make_request
    self._validate_conn(conn)
  File "/home/linuxbrew/.linuxbrew/opt/python3/lib/python3.6/site-packages/urllib3/connectionpool.py", line 850, in _validate_conn
    conn.connect()
  File "/home/linuxbrew/.linuxbrew/opt/python3/lib/python3.6/site-packages/urllib3/connection.py", line 284, in connect
    conn = self._new_conn()
  File "/home/linuxbrew/.linuxbrew/opt/python3/lib/python3.6/site-packages/urllib3/connection.py", line 150, in _new_conn
    self, "Failed to establish a new connection: %s" % e)
urllib3.exceptions.NewConnectionError: <urllib3.connection.VerifiedHTTPSConnection object at 0x7fc9a1c50ef0>: Failed to establish a new connection: [Errno 111] Connection refused

During handling of the above exception, another exception occurred:

Traceback (most recent call last):
  File "/home/linuxbrew/.linuxbrew/opt/python3/lib/python3.6/site-packages/kubeshell/client.py", line 35, in get_resource
    ret, namespaced_resource = self._call_api_client(resource)
  File "/home/linuxbrew/.linuxbrew/opt/python3/lib/python3.6/site-packages/kubeshell/client.py", line 65, in _call_api_client
    ret = self.v1.list_namespace(watch=False)
  File "/home/linuxbrew/.linuxbrew/opt/python3/lib/python3.6/site-packages/kubernetes/client/apis/core_v1_api.py", line 11614, in list_namespace
    (data) = self.list_namespace_with_http_info(**kwargs)
  File "/home/linuxbrew/.linuxbrew/opt/python3/lib/python3.6/site-packages/kubernetes/client/apis/core_v1_api.py", line 11707, in list_namespace_with_http_info
    collection_formats=collection_formats)
  File "/home/linuxbrew/.linuxbrew/opt/python3/lib/python3.6/site-packages/kubernetes/client/api_client.py", line 329, in call_api
    _return_http_data_only, collection_formats, _preload_content, _request_timeout)
  File "/home/linuxbrew/.linuxbrew/opt/python3/lib/python3.6/site-packages/kubernetes/client/api_client.py", line 153, in __call_api
    _request_timeout=_request_timeout)
  File "/home/linuxbrew/.linuxbrew/opt/python3/lib/python3.6/site-packages/kubernetes/client/api_client.py", line 361, in request
    headers=headers)
  File "/home/linuxbrew/.linuxbrew/opt/python3/lib/python3.6/site-packages/kubernetes/client/rest.py", line 240, in GET
    query_params=query_params)
  File "/home/linuxbrew/.linuxbrew/opt/python3/lib/python3.6/site-packages/kubernetes/client/rest.py", line 214, in request
    headers=headers)
  File "/home/linuxbrew/.linuxbrew/opt/python3/lib/python3.6/site-packages/urllib3/request.py", line 66, in request
    **urlopen_kw)
  File "/home/linuxbrew/.linuxbrew/opt/python3/lib/python3.6/site-packages/urllib3/request.py", line 87, in request_encode_url
    return self.urlopen(method, url, **extra_kw)
  File "/home/linuxbrew/.linuxbrew/opt/python3/lib/python3.6/site-packages/urllib3/poolmanager.py", line 321, in urlopen
    response = conn.urlopen(method, u.request_uri, **kw)
  File "/home/linuxbrew/.linuxbrew/opt/python3/lib/python3.6/site-packages/urllib3/connectionpool.py", line 668, in urlopen
    **response_kw)
  File "/home/linuxbrew/.linuxbrew/opt/python3/lib/python3.6/site-packages/urllib3/connectionpool.py", line 668, in urlopen
    **response_kw)
  File "/home/linuxbrew/.linuxbrew/opt/python3/lib/python3.6/site-packages/urllib3/connectionpool.py", line 668, in urlopen
    **response_kw)
  File "/home/linuxbrew/.linuxbrew/opt/python3/lib/python3.6/site-packages/urllib3/connectionpool.py", line 639, in urlopen
    _stacktrace=sys.exc_info()[2])
  File "/home/linuxbrew/.linuxbrew/opt/python3/lib/python3.6/site-packages/urllib3/util/retry.py", line 388, in increment
    raise MaxRetryError(_pool, url, error or ResponseError(cause))
urllib3.exceptions.MaxRetryError: HTTPSConnectionPool(host='localhost', port=443): Max retries exceeded with url: /api/v1/namespaces?watch=False (Caused by NewConnectionError('<urllib3.connection.VerifiedHTTPSConnection object at 0x7fc9a1c50ef0>: Failed to establish a new connection: [Errno 111] Connection refused',))
2017-11-12 12:57:41,802 [INFO] kubeshell.main cli:14 - session start
2017-11-12 12:57:41,803 [INFO] kubeshell.kubeshell run_cli:142 - running kube-shell event loop
2017-11-14 07:58:48,970 [INFO] kubeshell.main cli:14 - session start
2017-11-14 07:58:48,978 [INFO] kubeshell.kubeshell run_cli:142 - running kube-shell event loop
2017-11-21 07:44:31,749 [WARNING] kubeshell.client __init__:21 - unable to load kube-config
2017-11-21 07:44:32,174 [WARNING] kubeshell.client __init__:21 - unable to load kube-config
2017-11-21 07:44:32,197 [INFO] kubeshell.main cli:14 - session start
2017-11-21 07:44:32,198 [INFO] kubeshell.kubeshell run_cli:142 - running kube-shell event loop
2017-11-21 07:55:48,025 [INFO] kubeshell.main cli:14 - session start
2017-11-21 07:55:48,026 [INFO] kubeshell.kubeshell run_cli:142 - running kube-shell event loop
2017-11-23 08:13:52,018 [INFO] kubeshell.main cli:14 - session start
2017-11-23 08:13:52,037 [INFO] kubeshell.kubeshell run_cli:142 - running kube-shell event loop
2017-11-24 07:23:51,205 [INFO] kubeshell.main cli:14 - session start
2017-11-24 07:23:51,224 [INFO] kubeshell.kubeshell run_cli:142 - running kube-shell event loop
2017-11-24 07:24:20,920 [WARNING] kubeshell.kubeshell _:113 - failed namespace switching
Traceback (most recent call last):
  File "/home/linuxbrew/.linuxbrew/opt/python3/lib/python3.6/site-packages/kubeshell/kubeshell.py", line 110, in _
    KubeConfig.switch_to_next_namespace(Kubeshell.namespace)
  File "/home/linuxbrew/.linuxbrew/opt/python3/lib/python3.6/site-packages/kubeshell/kubeshell.py", line 77, in switch_to_next_namespace
    namespace_resources = completer.get_resources("namespace")
AttributeError: 'KubectlCompleter' object has no attribute 'get_resources'
2017-11-24 07:24:37,211 [INFO] kubeshell.main cli:14 - session start
2017-11-24 07:24:37,211 [INFO] kubeshell.kubeshell run_cli:142 - running kube-shell event loop
2017-11-24 07:24:50,102 [INFO] kubeshell.main cli:14 - session start
2017-11-24 07:24:50,102 [INFO] kubeshell.kubeshell run_cli:142 - running kube-shell event loop
2017-11-24 07:34:48,314 [INFO] kubeshell.main cli:14 - session start
2017-11-24 07:34:48,314 [INFO] kubeshell.kubeshell run_cli:142 - running kube-shell event loop
2017-11-29 08:09:18,342 [INFO] kubeshell.main cli:14 - session start
2017-11-29 08:09:18,350 [INFO] kubeshell.kubeshell run_cli:142 - running kube-shell event loop
2017-11-29 21:01:27,997 [INFO] kubeshell.main cli:14 - session start
2017-11-29 21:01:28,007 [INFO] kubeshell.kubeshell run_cli:142 - running kube-shell event loop
